<?xml version="1.0"?>
<robot name="3dof_robot_arm" xmlns:xacro="http://www.ros.org/wiki/xacro">

  <!-- Base Link -->
  <link name="base_link">
    <visual>
      <geometry>
        <cylinder radius="0.1" length="0.2"/>
      </geometry>
      <material name="blue">
        <color rgba="0 0 1 1"/>
      </material>
    </visual>
  </link>

  <!-- First Joint (Shoulder) -->
  <joint name="shoulder_joint" type="revolute">
    <parent link="base_link"/>
    <child link="link1"/>
    <origin xyz="0 0 0.1" rpy="0 0 0"/>
    <axis xyz="0 0 1"/>
    <limit effort="10.0" lower="-1.57" upper="1.57" velocity="1.0"/>
  </joint>

  <!-- First Link -->
  <link name="link1">
    <visual>
      <geometry>
        <box size="0.1 0.1 0.3"/>
      </geometry>
      <material name="red">
        <color rgba="1 0 0 1"/>
      </material>
    </visual>
  </link>

  <!-- Second Joint (Elbow) -->
  <joint name="elbow_joint" type="revolute">
    <parent link="link1"/>
    <child link="link2"/>
    <origin xyz="0 0 0.3" rpy="0 0 0"/>
    <axis xyz="0 1 0"/>
    <limit effort="10.0" lower="-1.57" upper="1.57" velocity="1.0"/>
  </joint>

  <!-- Second Link -->
  <link name="link2">
    <visual>
      <geometry>
        <box size="0.1 0.1 0.3"/>
      </geometry>
      <material name="green">
        <color rgba="0 1 0 1"/>
      </material>
    </visual>
  </link>

  <!-- Third Joint (Wrist) -->
  <joint name="wrist_joint" type="revolute">
    <parent link="link2"/>
    <child link="gripper_base"/>
    <origin xyz="0 0 0.3" rpy="0 0 0"/>
    <axis xyz="0 0 1"/>
    <limit effort="10.0" lower="-1.57" upper="1.57" velocity="1.0"/>
  </joint>

  <!-- Gripper Base -->
  <link name="gripper_base">
    <visual>
      <geometry>
        <box size="0.1 0.1 0.05"/>
      </geometry>
      <material name="gray">
        <color rgba="0.5 0.5 0.5 1"/>
      </material>
    </visual>
  </link>

  <!-- Left Finger -->
  <joint name="left_finger_joint" type="prismatic">
    <parent link="gripper_base"/>
    <child link="left_finger"/>
    <origin xyz="0.05 0 0.025" rpy="0 0 0"/>
    <axis xyz="1 0 0"/>
    <limit effort="5.0" lower="0.0" upper="0.04" velocity="0.01"/>
  </joint>

  <link name="left_finger">
    <visual>
      <geometry>
        <box size="0.02 0.06 0.05"/>
      </geometry>
      <material name="black">
        <color rgba="0 0 0 1"/>
      </material>
    </visual>
  </link>

  <!-- Right Finger -->
  <joint name="right_finger_joint" type="prismatic">
    <parent link="gripper_base"/>
    <child link="right_finger"/>
    <origin xyz="-0.05 0 0.025" rpy="0 0 0"/>
    <axis xyz="-1 0 0"/>
    <limit effort="5.0" lower="0.0" upper="0.04" velocity="0.01"/>
  </joint>

  <link name="right_finger">
    <visual>
      <geometry>
        <box size="0.02 0.06 0.05"/>
      </geometry>
      <material name="black">
        <color rgba="0 0 0 1"/>
      </material>
    </visual>
  </link>

</robot>
